Workbook

Sheet Purchase Tracker
A1: DIAMOND SUPPLIER PAYMENT TRACKER
A2: Enter invoices here. Full Amount auto-calculates from Weight × Rate. Enter Sales Return/QC Out as weight (ct/gm); return amount and 1.5% tax calculate automatically. Add every part payment in Partial Payment Log.
A3: Invoice No | B3: Supplier Name | C3: Invoice Date | D3: Weight (ct/gm) | E3: Rate | F3: Full Amount | G3: Sales Return (QC Out) Weight | H3: Sales Return Amount | I3: Tax 1.5% | J3: Total After Return + Tax | K3: Net Payable | L3: Payment Term Days | M3: Due Date | N3: Days Left/Overdue | O3: Due Bucket | P3: Total Paid | Q3: Balance | R3: Payment Status
A4: J016-2026-27 | B4: JEEYA DIAMOND | C4: 46190 | D4: 52.49 | E4: 40000 | F4: =IF(OR(D4="",E4=""),"",D4*E4) -> 2099600 | G4: 3.52 | H4: =IF(A4="","",N(G4)*E4) -> 140800 | I4: =IF(F4="","",(F4-H4)*1.5%) -> 29382 | J4: =IF(F4="","",(F4-H4)+I4) -> 1988182 | K4: =IF(F4="","",J4) -> 1988182 | L4: 90 | M4: =IF(OR(C4="",L4=""),"",C4+L4) -> 46280 | N4: =IF(M4="","",M4-TODAY()) -> -17 | O4: =IF(L4="","",L4&" Day Due") -> 90 Day Due | P4: =IF(A4="","",SUMIFS('Partial Payment Log'!$E$4:$E$501,'Partial Payment Log'!$C$4:$C$501,A4)) -> 0 | Q4: =IF(A4="","",K4-P4) -> 1988182 | R4: =IF(A4="","",IF(Q4<=0,IF(Q4<0,"Overpaid","Paid"),IF(P4>0,"Part Paid","Unpaid"))) -> Unpaid
A5: J016-2026-27 | B5: JEEYA DIAMOND | C5: 46193 | D5: 28.59 | E5: 40000 | F5: =IF(OR(D5="",E5=""),"",D5*E5) -> 1143600 | G5: 11.7 | H5: =IF(A5="","",N(G5)*E5) -> 468000 | I5: =IF(F5="","",(F5-H5)*1.5%) -> 10134 | J5: =IF(F5="","",(F5-H5)+I5) -> 685734 | K5: =IF(F5="","",J5) -> 685734 | L5: 90 | M5: =IF(OR(C5="",L5=""),"",C5+L5) -> 46283 | N5: =IF(M5="","",M5-TODAY()) -> -14 | O5: =IF(L5="","",L5&" Day Due") -> 90 Day Due | P5: =IF(A5="","",SUMIFS('Partial Payment Log'!$E$4:$E$501,'Partial Payment Log'!$C$4:$C$501,A5)) -> 0 | Q5: =IF(A5="","",K5-P5) -> 685734 | R5: =IF(A5="","",IF(Q5<=0,IF(Q5<0,"Overpaid","Paid"),IF(P5>0,"Part Paid","Unpaid"))) -> Unpaid
A6: J020-2026-27 | B6: JEEYA DIAMOND | C6: 46195 | D6: 85.47 | E6: 40000 | F6: =IF(OR(D6="",E6=""),"",D6*E6) -> 3418800 | G6: 12.45 | H6: =IF(A6="","",N(G6)*E6) -> 498000 | I6: =IF(F6="","",(F6-H6)*1.5%) -> 43812 | J6: =IF(F6="","",(F6-H6)+I6) -> 2964612 | K6: =IF(F6="","",J6) -> 2964612 | L6: 90 | M6: =IF(OR(C6="",L6=""),"",C6+L6) -> 46285 | N6: =IF(M6="","",M6-TODAY()) -> -12 | O6: =IF(L6="","",L6&" Day Due") -> 90 Day Due | P6: =IF(A6="","",SUMIFS('Partial Payment Log'!$E$4:$E$501,'Partial Payment Log'!$C$4:$C$501,A6)) -> 0 | Q6: =IF(A6="","",K6-P6) -> 2964612 | R6: =IF(A6="","",IF(Q6<=0,IF(Q6<0,"Overpaid","Paid"),IF(P6>0,"Part Paid","Unpaid"))) -> Unpaid
A7: J023-2026-27 | B7: JEEYA DIAMOND | C7: 46199 | D7: 34.59 | E7: 40000 | F7: =IF(OR(D7="",E7=""),"",D7*E7) -> 1383600 | G7: 6.92 | H7: =IF(A7="","",N(G7)*E7) -> 276800 | I7: =IF(F7="","",(F7-H7)*1.5%) -> 16602 | J7: =IF(F7="","",(F7-H7)+I7) -> 1123402 | K7: =IF(F7="","",J7) -> 1123402 | L7: 90 | M7: =IF(OR(C7="",L7=""),"",C7+L7) -> 46289 | N7: =IF(M7="","",M7-TODAY()) -> -8 | O7: =IF(L7="","",L7&" Day Due") -> 90 Day Due | P7: =IF(A7="","",SUMIFS('Partial Payment Log'!$E$4:$E$501,'Partial Payment Log'!$C$4:$C$501,A7)) -> 0 | Q7: =IF(A7="","",K7-P7) -> 1123402 | R7: =IF(A7="","",IF(Q7<=0,IF(Q7<0,"Overpaid","Paid"),IF(P7>0,"Part Paid","Unpaid"))) -> Unpaid
A8: J026-2026-27 | B8: JEEYA DIAMOND | C8: 46202 | D8: 19.89 | E8: 40000 | F8: =IF(OR(D8="",E8=""),"",D8*E8) -> 795600 | G8: 0 | H8: =IF(A8="","",N(G8)*E8) -> 0 | I8: =IF(F8="","",(F8-H8)*1.5%) -> 11934 | J8: =IF(F8="","",(F8-H8)+I8) -> 807534 | K8: =IF(F8="","",J8) -> 807534 | L8: 90 | M8: =IF(OR(C8="",L8=""),"",C8+L8) -> 46292 | N8: =IF(M8="","",M8-TODAY()) -> -5 | O8: =IF(L8="","",L8&" Day Due") -> 90 Day Due | P8: =IF(A8="","",SUMIFS('Partial Payment Log'!$E$4:$E$501,'Partial Payment Log'!$C$4:$C$501,A8)) -> 0 | Q8: =IF(A8="","",K8-P8) -> 807534 | R8: =IF(A8="","",IF(Q8<=0,IF(Q8<0,"Overpaid","Paid"),IF(P8>0,"Part Paid","Unpaid"))) -> Unpaid
A9: J026-2026-27-2 | B9: JEEYA DIAMOND | C9: 46202 | D9: 22.04 | E9: 40000 | F9: =IF(OR(D9="",E9=""),"",D9*E9) -> 881600 | G9: 0 | H9: =IF(A9="","",N(G9)*E9) -> 0 | I9: =IF(F9="","",(F9-H9)*1.5%) -> 13224 | J9: =IF(F9="","",(F9-H9)+I9) -> 894824 | K9: =IF(F9="","",J9) -> 894824 | L9: 90 | M9: =IF(OR(C9="",L9=""),"",C9+L9) -> 46292 | N9: =IF(M9="","",M9-TODAY()) -> -5 | O9: =IF(L9="","",L9&" Day Due") -> 90 Day Due | P9: =IF(A9="","",SUMIFS('Partial Payment Log'!$E$4:$E$501,'Partial Payment Log'!$C$4:$C$501,A9)) -> 0 | Q9: =IF(A9="","",K9-P9) -> 894824 | R9: =IF(A9="","",IF(Q9<=0,IF(Q9<0,"Overpaid","Paid"),IF(P9>0,"Part Paid","Unpaid"))) -> Unpaid
A10: OPEN-JEEYA | B10: JEEYA DIAMOND | C10: 46113 | D10: 246.815 | E10: 40000 | F10: =IF(OR(D10="",E10=""),"",D10*E10) -> 9872600 | G10: 0 | H10: =IF(A10="","",N(G10)*E10) -> 0 | I10: =IF(F10="","",(F10-H10)*1.5%) -> 148089 | J10: =IF(F10="","",(F10-H10)+I10) -> 10020689 | K10: =IF(F10="","",J10) -> 10020689 | L10: 90 | M10: =IF(OR(C10="",L10=""),"",C10+L10) -> 46203 | N10: =IF(M10="","",M10-TODAY()) -> -94 | O10: =IF(L10="","",L10&" Day Due") -> 90 Day Due | P10: =IF(A10="","",SUMIFS('Partial Payment Log'!$E$4:$E$501,'Partial Payment Log'!$C$4:$C$501,A10)) -> 10901192 | Q10: =IF(A10="","",K10-P10) -> -880503 | R10: =IF(A10="","",IF(Q10<=0,IF(Q10<0,"Overpaid","Paid"),IF(P10>0,"Part Paid","Unpaid"))) -> Overpaid
A11: OPEN--RITESH | B11: RITESH EXPORT | C11: 46113 | D11: 154.17032 | E11: 40000 | F11: =IF(OR(D11="",E11=""),"",D11*E11) -> 6166812.8 | G11: 0 | H11: =IF(A11="","",N(G11)*E11) -> 0 | I11: =IF(F11="","",(F11-H11)*1.5%) -> 92502.192 | J11: =IF(F11="","",(F11-H11)+I11) -> 6259315 | K11: =IF(F11="","",J11) -> 6259315 | L11: 90 | M11: =IF(OR(C11="",L11=""),"",C11+L11) -> 46203 | N11: =IF(M11="","",M11-TODAY()) -> -94 | O11: =IF(L11="","",L11&" Day Due") -> 90 Day Due | P11: =IF(A11="","",SUMIFS('Partial Payment Log'!$E$4:$E$501,'Partial Payment Log'!$C$4:$C$501,A11)) -> 6259315 | Q11: =IF(A11="","",K11-P11) -> 0 | R11: =IF(A11="","",IF(Q11<=0,IF(Q11<0,"Overpaid","Paid"),IF(P11>0,"Part Paid","Unpaid"))) -> Paid
A12: LS/83/26-27 | B12: RITESH EXPORT | C12: 46169 | D12: 8.6319951 | E12: 40000 | F12: =IF(OR(D12="",E12=""),"",D12*E12) -> 345279.8 | G12: 0 | H12: =IF(A12="","",N(G12)*E12) -> 0 | I12: =IF(F12="","",(F12-H12)*1.5%) -> 5179.197 | J12: =IF(F12="","",(F12-H12)+I12) -> 350459 | K12: =IF(F12="","",J12) -> 350459 | L12: 90 | M12: =IF(OR(C12="",L12=""),"",C12+L12) -> 46259 | N12: =IF(M12="","",M12-TODAY()) -> -38 | O12: =IF(L12="","",L12&" Day Due") -> 90 Day Due | P12: =IF(A12="","",SUMIFS('Partial Payment Log'!$E$4:$E$501,'Partial Payment Log'!$C$4:$C$501,A12)) -> 350459 | Q12: =IF(A12="","",K12-P12) -> 5.8207661e-11 | R12: =IF(A12="","",IF(Q12<=0,IF(Q12<0,"Overpaid","Paid"),IF(P12>0,"Part Paid","Unpaid"))) -> Part Paid
A13: OPEN-APPLE | B13: APPLE GEMS | C13: 46113 | D13: 396.83663 | E13: 40000 | F13: =IF(OR(D13="",E13=""),"",D13*E13) -> 15873465 | G13: 0 | H13: =IF(A13="","",N(G13)*E13) -> 0 | I13: =IF(F13="","",(F13-H13)*1.5%) -> 238101.98 | J13: =IF(F13="","",(F13-H13)+I13) -> 16111567 | K13: =IF(F13="","",J13) -> 16111567 | L13: 90 | M13: =IF(OR(C13="",L13=""),"",C13+L13) -> 46203 | N13: =IF(M13="","",M13-TODAY()) -> -94 | O13: =IF(L13="","",L13&" Day Due") -> 90 Day Due | P13: =IF(A13="","",SUMIFS('Partial Payment Log'!$E$4:$E$501,'Partial Payment Log'!$C$4:$C$501,A13)) -> 16124397 | Q13: =IF(A13="","",K13-P13) -> -12830 | R13: =IF(A13="","",IF(Q13<=0,IF(Q13<0,"Overpaid","Paid"),IF(P13>0,"Part Paid","Unpaid"))) -> Overpaid
A14: OPEN-S&M | B14: S & M DIAMONDS . | C14: 46113 | D14: 98.138473 | E14: 40000 | F14: =IF(OR(D14="",E14=""),"",D14*E14) -> 3925538.9 | G14: 0 | H14: =IF(A14="","",N(G14)*E14) -> 0 | I14: =IF(F14="","",(F14-H14)*1.5%) -> 58883.084 | J14: =IF(F14="","",(F14-H14)+I14) -> 3984422 | K14: =IF(F14="","",J14) -> 3984422 | L14: 90 | M14: =IF(OR(C14="",L14=""),"",C14+L14) -> 46203 | N14: =IF(M14="","",M14-TODAY()) -> -94 | O14: =IF(L14="","",L14&" Day Due") -> 90 Day Due | P14: =IF(A14="","",SUMIFS('Partial Payment Log'!$E$4:$E$501,'Partial Payment Log'!$C$4:$C$501,A14)) -> 5984221 | Q14: =IF(A14="","",K14-P14) -> -1999799 | R14: =IF(A14="","",IF(Q14<=0,IF(Q14<0,"Overpaid","Paid"),IF(P14>0,"Part Paid","Unpaid"))) -> Overpaid
A15: SM/62/26-27 | B15: S & M DIAMONDS . | C15: 46174 | D15: 78.316 | E15: 41500 | F15: =IF(OR(D15="",E15=""),"",D15*E15) -> 3250114 | G15: 28.55 | H15: =IF(A15="","",N(G15)*E15) -> 1184825 | I15: =IF(F15="","",(F15-H15)*1.5%) -> 30979.335 | J15: =IF(F15="","",(F15-H15)+I15) -> 2096268.3 | K15: =IF(F15="","",J15) -> 2096268.3 | L15: 90 | M15: =IF(OR(C15="",L15=""),"",C15+L15) -> 46264 | N15: =IF(M15="","",M15-TODAY()) -> -33 | O15: =IF(L15="","",L15&" Day Due") -> 90 Day Due | P15: =IF(A15="","",SUMIFS('Partial Payment Log'!$E$4:$E$501,'Partial Payment Log'!$C$4:$C$501,A15)) -> 1000000 | Q15: =IF(A15="","",K15-P15) -> 1096268.3 | R15: =IF(A15="","",IF(Q15<=0,IF(Q15<0,"Overpaid","Paid"),IF(P15>0,"Part Paid","Unpaid"))) -> Part Paid
... A17: OPEN-AV | B17: AV DIAMONDS | C17: 46113 | D17: 459.42772 | E17: 40000 | F17: =IF(OR(D17="",E17=""),"",D17*E17) -> 18377109 | G17: 0 | H17: =IF(A17="","",N(G17)*E17) -> 0 | I17: =IF(F17="","",(F17-H17)*1.5%) -> 275656.63 | J17: =IF(F17="","",(F17-H17)+I17) -> 18652765 | K17: =IF(F17="","",J17) -> 18652765 | L17: 90 | M17: =IF(OR(C17="",L17=""),"",C17+L17) -> 46203 | N17: =IF(M17="","",M17-TODAY()) -> -94 | O17: =IF(L17="","",L17&" Day Due") -> 90 Day Due | P17: =IF(A17="","",SUMIFS('Partial Payment Log'!$E$4:$E$501,'Partial Payment Log'!$C$4:$C$501,A17)) -> 22927511 | Q17: =IF(A17="","",K17-P17) -> -4274745.8 | R17: =IF(A17="","",IF(Q17<=0,IF(Q17<0,"Overpaid","Paid"),IF(P17>0,"Part Paid","Unpaid"))) -> Overpaid
A18: 3 | B18: AV DIAMONDS | C18: 46167 | D18: 102.105 | E18: 41000 | F18: =IF(OR(D18="",E18=""),"",D18*E18) -> 4186305 | G18: 33.845006 | H18: =IF(A18="","",N(G18)*E18) -> 1387645.2 | I18: =IF(F18="","",(F18-H18)*1.5%) -> 41979.896 | J18: =IF(F18="","",(F18-H18)+I18) -> 2840639.6 | K18: =IF(F18="","",J18) -> 2840639.6 | L18: 90 | M18: =IF(OR(C18="",L18=""),"",C18+L18) -> 46257 | N18: =IF(M18="","",M18-TODAY()) -> -40 | O18: =IF(L18="","",L18&" Day Due") -> 90 Day Due | P18: =IF(A18="","",SUMIFS('Partial Payment Log'!$E$4:$E$501,'Partial Payment Log'!$C$4:$C$501,A18)) -> 0 | Q18: =IF(A18="","",K18-P18) -> 2840639.6 | R18: =IF(A18="","",IF(Q18<=0,IF(Q18<0,"Overpaid","Paid"),IF(P18>0,"Part Paid","Unpaid"))) -> Unpaid
A19: 4 | B19: AV DIAMONDS | C19: 46167 | D19: 38.67 | E19: 41000 | F19: =IF(OR(D19="",E19=""),"",D19*E19) -> 1585470 | G19: 15.58 | H19: =IF(A19="","",N(G19)*E19) -> 638780 | I19: =IF(F19="","",(F19-H19)*1.5%) -> 14200.35 | J19: =IF(F19="","",(F19-H19)+I19) -> 960890.35 | K19: =IF(F19="","",J19) -> 960890.35 | L19: 90 | M19: =IF(OR(C19="",L19=""),"",C19+L19) -> 46257 | N19: =IF(M19="","",M19-TODAY()) -> -40 | O19: =IF(L19="","",L19&" Day Due") -> 90 Day Due | P19: =IF(A19="","",SUMIFS('Partial Payment Log'!$E$4:$E$501,'Partial Payment Log'!$C$4:$C$501,A19)) -> 0 | Q19: =IF(A19="","",K19-P19) -> 960890.35 | R19: =IF(A19="","",IF(Q19<=0,IF(Q19<0,"Overpaid","Paid"),IF(P19>0,"Part Paid","Unpaid"))) -> Unpaid
A20: 5 | B20: AV DIAMONDS | C20: 46180 | D20: 69.53 | E20: 41000 | F20: =IF(OR(D20="",E20=""),"",D20*E20) -> 2850730 | G20: 0 | H20: =IF(A20="","",N(G20)*E20) -> 0 | I20: =IF(F20="","",(F20-H20)*1.5%) -> 42760.95 | J20: =IF(F20="","",(F20-H20)+I20) -> 2893491 | K20: =IF(F20="","",J20) -> 2893491 | L20: 90 | M20: =IF(OR(C20="",L20=""),"",C20+L20) -> 46270 | N20: =IF(M20="","",M20-TODAY()) -> -27 | O20: =IF(L20="","",L20&" Day Due") -> 90 Day Due | P20: =IF(A20="","",SUMIFS('Partial Payment Log'!$E$4:$E$501,'Partial Payment Log'!$C$4:$C$501,A20)) -> 0 | Q20: =IF(A20="","",K20-P20) -> 2893491 | R20: =IF(A20="","",IF(Q20<=0,IF(Q20<0,"Overpaid","Paid"),IF(P20>0,"Part Paid","Unpaid"))) -> Unpaid
A21: 6 | B21: AV DIAMONDS | C21: 46120 | D21: 0.45359606 | E21: 40000 | F21: =IF(OR(D21="",E21=""),"",D21*E21) -> 18143.842 | G21: 0 | H21: =IF(A21="","",N(G21)*E21) -> 0 | I21: =IF(F21="","",(F21-H21)*1.5%) -> 272.15764 | J21: =IF(F21="","",(F21-H21)+I21) -> 18416 | K21: =IF(F21="","",J21) -> 18416 | L21: 90 | M21: =IF(OR(C21="",L21=""),"",C21+L21) -> 46210 | N21: =IF(M21="","",M21-TODAY()) -> -87 | O21: =IF(L21="","",L21&" Day Due") -> 90 Day Due | P21: =IF(A21="","",SUMIFS('Partial Payment Log'!$E$4:$E$501,'Partial Payment Log'!$C$4:$C$501,A21)) -> 0 | Q21: =IF(A21="","",K21-P21) -> 18416 | R21: =IF(A21="","",IF(Q21<=0,IF(Q21<0,"Overpaid","Paid"),IF(P21>0,"Part Paid","Unpaid"))) -> Unpaid
A22: 7 | B22: AV DIAMONDS | C22: 46147 | D22: 0.7146798 | E22: 40000 | F22: =IF(OR(D22="",E22=""),"",D22*E22) -> 28587.192 | G22: 0 | H22: =IF(A22="","",N(G22)*E22) -> 0 | I22: =IF(F22="","",(F22-H22)*1.5%) -> 428.80788 | J22: =IF(F22="","",(F22-H22)+I22) -> 29016 | K22: =IF(F22="","",J22) -> 29016 | L22: 90 | M22: =IF(OR(C22="",L22=""),"",C22+L22) -> 46237 | N22: =IF(M22="","",M22-TODAY()) -> -60 | O22: =IF(L22="","",L22&" Day Due") -> 90 Day Due | P22: =IF(A22="","",SUMIFS('Partial Payment Log'!$E$4:$E$501,'Partial Payment Log'!$C$4:$C$501,A22)) -> 0 | Q22: =IF(A22="","",K22-P22) -> 29016 | R22: =IF(A22="","",IF(Q22<=0,IF(Q22<0,"Overpaid","Paid"),IF(P22>0,"Part Paid","Unpaid"))) -> Unpaid
A23: 8 | B23: AV DIAMONDS | C23: 46174 | D23: 3.5186207 | E23: 40000 | F23: =IF(OR(D23="",E23=""),"",D23*E23) -> 140744.83 | G23: 0 | H23: =IF(A23="","",N(G23)*E23) -> 0 | I23: =IF(F23="","",(F23-H23)*1.5%) -> 2111.1724 | J23: =IF(F23="","",(F23-H23)+I23) -> 142856 | K23: =IF(F23="","",J23) -> 142856 | L23: 90 | M23: =IF(OR(C23="",L23=""),"",C23+L23) -> 46264 | N23: =IF(M23="","",M23-TODAY()) -> -33 | O23: =IF(L23="","",L23&" Day Due") -> 90 Day Due | P23: =IF(A23="","",SUMIFS('Partial Payment Log'!$E$4:$E$501,'Partial Payment Log'!$C$4:$C$501,A23)) -> 0 | Q23: =IF(A23="","",K23-P23) -> 142856 | R23: =IF(A23="","",IF(Q23<=0,IF(Q23<0,"Overpaid","Paid"),IF(P23>0,"Part Paid","Unpaid"))) -> Unpaid
A24: OPEN -BAV | B24: BHAVYA JEWELS | C24: 46113 | D24: 74.524907 | E24: 41000 | F24: =IF(OR(D24="",E24=""),"",D24*E24) -> 3055521.2 | G24: 0 | H24: =IF(A24="","",N(G24)*E24) -> 0 | I24: =IF(F24="","",(F24-H24)*1.5%) -> 45832.818 | J24: =IF(F24="","",(F24-H24)+I24) -> 3101354 | K24: =IF(F24="","",J24) -> 3101354 | L24: 90 | M24: =IF(OR(C24="",L24=""),"",C24+L24) -> 46203 | N24: =IF(M24="","",M24-TODAY()) -> -94 | O24: =IF(L24="","",L24&" Day Due") -> 90 Day Due | P24: =IF(A24="","",SUMIFS('Partial Payment Log'!$E$4:$E$501,'Partial Payment Log'!$C$4:$C$501,A24)) -> 3000000 | Q24: =IF(A24="","",K24-P24) -> 101354 | R24: =IF(A24="","",IF(Q24<=0,IF(Q24<0,"Overpaid","Paid"),IF(P24>0,"Part Paid","Unpaid"))) -> Part Paid
A25: 1 | B25: BHAVYA JEWELS | C25: 46178 | D25: 76.78 | E25: 42000 | F25: =IF(OR(D25="",E25=""),"",D25*E25) -> 3224760 | G25: 47.49 | H25: =IF(A25="","",N(G25)*E25) -> 1994580 | I25: =IF(F25="","",(F25-H25)*1.5%) -> 18452.7 | J25: =IF(F25="","",(F25-H25)+I25) -> 1248632.7 | K25: =IF(F25="","",J25) -> 1248632.7 | L25: 90 | M25: =IF(OR(C25="",L25=""),"",C25+L25) -> 46268 | N25: =IF(M25="","",M25-TODAY()) -> -29 | O25: =IF(L25="","",L25&" Day Due") -> 90 Day Due | P25: =IF(A25="","",SUMIFS('Partial Payment Log'!$E$4:$E$501,'Partial Payment Log'!$C$4:$C$501,A25)) -> 0 | Q25: =IF(A25="","",K25-P25) -> 1248632.7 | R25: =IF(A25="","",IF(Q25<=0,IF(Q25<0,"Overpaid","Paid"),IF(P25>0,"Part Paid","Unpaid"))) -> Unpaid
A26: OPEN-ARIA | B26: ARYAN GEMS | C26: 46113 | D26: 268.04095 | E26: 41000 | F26: =IF(OR(D26="",E26=""),"",D26*E26) -> 10989679 | G26: 0 | H26: =IF(A26="","",N(G26)*E26) -> 0 | I26: =IF(F26="","",(F26-H26)*1.5%) -> 164845.18 | J26: =IF(F26="","",(F26-H26)+I26) -> 11154524 | K26: =IF(F26="","",J26) -> 11154524 | L26: 90 | M26: =IF(OR(C26="",L26=""),"",C26+L26) -> 46203 | N26: =IF(M26="","",M26-TODAY()) -> -94 | O26: =IF(L26="","",L26&" Day Due") -> 90 Day Due | P26: =IF(A26="","",SUMIFS('Partial Payment Log'!$E$4:$E$501,'Partial Payment Log'!$C$4:$C$501,A26)) -> 12989944 | Q26: =IF(A26="","",K26-P26) -> -1835420 | R26: =IF(A26="","",IF(Q26<=0,IF(Q26<0,"Overpaid","Paid"),IF(P26>0,"Part Paid","Unpaid"))) -> Overpaid
A27: AEI01 | B27: ARYAN GEMS | C27: 46168 | D27: 165.912 | E27: 41500 | F27: =IF(OR(D27="",E27=""),"",D27*E27) -> 6885348 | G27: 0 | H27: =IF(A27="","",N(G27)*E27) -> 0 | I27: =IF(F27="","",(F27-H27)*1.5%) -> 103280.22 | J27: =IF(F27="","",(F27-H27)+I27) -> 6988628.2 | K27: =IF(F27="","",J27) -> 6988628.2 | L27: 90 | M27: =IF(OR(C27="",L27=""),"",C27+L27) -> 46258 | N27: =IF(M27="","",M27-TODAY()) -> -39 | O27: =IF(L27="","",L27&" Day Due") -> 90 Day Due | P27: =IF(A27="","",SUMIFS('Partial Payment Log'!$E$4:$E$501,'Partial Payment Log'!$C$4:$C$501,A27)) -> 0 | Q27: =IF(A27="","",K27-P27) -> 6988628.2 | R27: =IF(A27="","",IF(Q27<=0,IF(Q27<0,"Overpaid","Paid"),IF(P27>0,"Part Paid","Unpaid"))) -> Unpaid
A28: AEI02 | B28: ARYAN GEMS | C28: 46178 | D28: 22.4 | E28: 41000 | F28: =IF(OR(D28="",E28=""),"",D28*E28) -> 918400 | G28: 0 | H28: =IF(A28="","",N(G28)*E28) -> 0 | I28: =IF(F28="","",(F28-H28)*1.5%) -> 13776 | J28: =IF(F28="","",(F28-H28)+I28) -> 932176 | K28: =IF(F28="","",J28) -> 932176 | L28: 90 | M28: =IF(OR(C28="",L28=""),"",C28+L28) -> 46268 | N28: =IF(M28="","",M28-TODAY()) -> -29 | O28: =IF(L28="","",L28&" Day Due") -> 90 Day Due | P28: =IF(A28="","",SUMIFS('Partial Payment Log'!$E$4:$E$501,'Partial Payment Log'!$C$4:$C$501,A28)) -> 0 | Q28: =IF(A28="","",K28-P28) -> 932176 | R28: =IF(A28="","",IF(Q28<=0,IF(Q28<0,"Overpaid","Paid"),IF(P28>0,"Part Paid","Unpaid"))) -> Unpaid
A29: AEI03 | B29: ARYAN GEMS | C29: 46178 | D29: 15 | E29: 34000 | F29: =IF(OR(D29="",E29=""),"",D29*E29) -> 510000 | G29: 0 | H29: =IF(A29="","",N(G29)*E29) -> 0 | I29: =IF(F29="","",(F29-H29)*1.5%) -> 7650 | J29: =IF(F29="","",(F29-H29)+I29) -> 517650 | K29: =IF(F29="","",J29) -> 517650 | L29: 90 | M29: =IF(OR(C29="",L29=""),"",C29+L29) -> 46268 | N29: =IF(M29="","",M29-TODAY()) -> -29 | O29: =IF(L29="","",L29&" Day Due") -> 90 Day Due | P29: =IF(A29="","",SUMIFS('Partial Payment Log'!$E$4:$E$501,'Partial Payment Log'!$C$4:$C$501,A29)) -> 0 | Q29: =IF(A29="","",K29-P29) -> 517650 | R29: =IF(A29="","",IF(Q29<=0,IF(Q29<0,"Overpaid","Paid"),IF(P29>0,"Part Paid","Unpaid"))) -> Unpaid
A30: AEI04 | B30: ARYAN GEMS | C30: 46178 | D30: 12.2 | E30: 43000 | F30: =IF(OR(D30="",E30=""),"",D30*E30) -> 524600 | G30: 2.89 | H30: =IF(A30="","",N(G30)*E30) -> 124270 | I30: =IF(F30="","",(F30-H30)*1.5%) -> 6004.95 | J30: =IF(F30="","",(F30-H30)+I30) -> 406334.95 | K30: =IF(F30="","",J30) -> 406334.95 | L30: 90 | M30: =IF(OR(C30="",L30=""),"",C30+L30) -> 46268 | N30: =IF(M30="","",M30-TODAY()) -> -29 | O30: =IF(L30="","",L30&" Day Due") -> 90 Day Due | P30: =IF(A30="","",SUMIFS('Partial Payment Log'!$E$4:$E$501,'Partial Payment Log'!$C$4:$C$501,A30)) -> 0 | Q30: =IF(A30="","",K30-P30) -> 406334.95 | R30: =IF(A30="","",IF(Q30<=0,IF(Q30<0,"Overpaid","Paid"),IF(P30>0,"Part Paid","Unpaid"))) -> Unpaid
A31: AEI05 | B31: ARYAN GEMS | C31: 46189 | D31: 5.29 | E31: 54000 | F31: =IF(OR(D31="",E31=""),"",D31*E31) -> 285660 | G31: 2.59 | H31: =IF(A31="","",N(G31)*E31) -> 139860 | I31: =IF(F31="","",(F31-H31)*1.5%) -> 2187 | J31: =IF(F31="","",(F31-H31)+I31) -> 147987 | K31: =IF(F31="","",J31) -> 147987 | L31: 90 | M31: =IF(OR(C31="",L31=""),"",C31+L31) -> 46279 | N31: =IF(M31="","",M31-TODAY()) -> -18 | O31: =IF(L31="","",L31&" Day Due") -> 90 Day Due | P31: =IF(A31="","",SUMIFS('Partial Payment Log'!$E$4:$E$501,'Partial Payment Log'!$C$4:$C$501,A31)) -> 0 | Q31: =IF(A31="","",K31-P31) -> 147987 | R31: =IF(A31="","",IF(Q31<=0,IF(Q31<0,"Overpaid","Paid"),IF(P31>0,"Part Paid","Unpaid"))) -> Unpaid
A32: AEI06 | B32: ARYAN GEMS | C32: 46189 | D32: 7.383 | E32: 70000 | F32: =IF(OR(D32="",E32=""),"",D32*E32) -> 516810 | G32: 4.01 | H32: =IF(A32="","",N(G32)*E32) -> 280700 | I32: =IF(F32="","",(F32-H32)*1.5%) -> 3541.65 | J32: =IF(F32="","",(F32-H32)+I32) -> 239651.65 | K32: =IF(F32="","",J32) -> 239651.65 | L32: 90 | M32: =IF(OR(C32="",L32=""),"",C32+L32) -> 46279 | N32: =IF(M32="","",M32-TODAY()) -> -18 | O32: =IF(L32="","",L32&" Day Due") -> 90 Day Due | P32: =IF(A32="","",SUMIFS('Partial Payment Log'!$E$4:$E$501,'Partial Payment Log'!$C$4:$C$501,A32)) -> 0 | Q32: =IF(A32="","",K32-P32) -> 239651.65 | R32: =IF(A32="","",IF(Q32<=0,IF(Q32<0,"Overpaid","Paid"),IF(P32>0,"Part Paid","Unpaid"))) -> Unpaid
A33: AEI07 | B33: ARYAN GEMS | C33: 46189 | D33: 1.35 | E33: 62000 | F33: =IF(OR(D33="",E33=""),"",D33*E33) -> 83700 | G33: 0.51 | H33: =IF(A33="","",N(G33)*E33) -> 31620 | I33: =IF(F33="","",(F33-H33)*1.5%) -> 781.2 | J33: =IF(F33="","",(F33-H33)+I33) -> 52861.2 | K33: =IF(F33="","",J33) -> 52861.2 | L33: 90 | M33: =IF(OR(C33="",L33=""),"",C33+L33) -> 46279 | N33: =IF(M33="","",M33-TODAY()) -> -18 | O33: =IF(L33="","",L33&" Day Due") -> 90 Day Due | P33: =IF(A33="","",SUMIFS('Partial Payment Log'!$E$4:$E$501,'Partial Payment Log'!$C$4:$C$501,A33)) -> 0 | Q33: =IF(A33="","",K33-P33) -> 52861.2 | R33: =IF(A33="","",IF(Q33<=0,IF(Q33<0,"Overpaid","Paid"),IF(P33>0,"Part Paid","Unpaid"))) -> Unpaid
A34: AEI08 | B34: ARYAN GEMS | C34: 46190 | D34: 40.291 | E34: 41500 | F34: =IF(OR(D34="",E34=""),"",D34*E34) -> 1672076.5 | G34: 22.27 | H34: =IF(A34="","",N(G34)*E34) -> 924205 | I34: =IF(F34="","",(F34-H34)*1.5%) -> 11218.072 | J34: =IF(F34="","",(F34-H34)+I34) -> 759089.57 | K34: =IF(F34="","",J34) -> 759089.57 | L34: 90 | M34: =IF(OR(C34="",L34=""),"",C34+L34) -> 46280 | N34: =IF(M34="","",M34-TODAY()) -> -17 | O34: =IF(L34="","",L34&" Day Due") -> 90 Day Due | P34: =IF(A34="","",SUMIFS('Partial Payment Log'!$E$4:$E$501,'Partial Payment Log'!$C$4:$C$501,A34)) -> 0 | Q34: =IF(A34="","",K34-P34) -> 759089.57 | R34: =IF(A34="","",IF(Q34<=0,IF(Q34<0,"Overpaid","Paid"),IF(P34>0,"Part Paid","Unpaid"))) -> Unpaid
A35: AEI09 | B35: ARYAN GEMS | C35: 46196 | D35: 7.91 | E35: 43000 | F35: =IF(OR(D35="",E35=""),"",D35*E35) -> 340130 | G35: 2.31 | H35: =IF(A35="","",N(G35)*E35) -> 99330 | I35: =IF(F35="","",(F35-H35)*1.5%) -> 3612 | J35: =IF(F35="","",(F35-H35)+I35) -> 244412 | K35: =IF(F35="","",J35) -> 244412 | L35: 90 | M35: =IF(OR(C35="",L35=""),"",C35+L35) -> 46286 | N35: =IF(M35="","",M35-TODAY()) -> -11 | O35: =IF(L35="","",L35&" Day Due") -> 90 Day Due | P35: =IF(A35="","",SUMIFS('Partial Payment Log'!$E$4:$E$501,'Partial Payment Log'!$C$4:$C$501,A35)) -> 0 | Q35: =IF(A35="","",K35-P35) -> 244412 | R35: =IF(A35="","",IF(Q35<=0,IF(Q35<0,"Overpaid","Paid"),IF(P35>0,"Part Paid","Unpaid"))) -> Unpaid
A36: AEI10 | B36: ARYAN GEMS | C36: 46196 | D36: 11.04 | E36: 43000 | F36: =IF(OR(D36="",E36=""),"",D36*E36) -> 474720 | G36: 5.2 | H36: =IF(A36="","",N(G36)*E36) -> 223600 | I36: =IF(F36="","",(F36-H36)*1.5%) -> 3766.8 | J36: =IF(F36="","",(F36-H36)+I36) -> 254886.8 | K36: =IF(F36="","",J36) -> 254886.8 | L36: 90 | M36: =IF(OR(C36="",L36=""),"",C36+L36) -> 46286 | N36: =IF(M36="","",M36-TODAY()) -> -11 | O36: =IF(L36="","",L36&" Day Due") -> 90 Day Due | P36: =IF(A36="","",SUMIFS('Partial Payment Log'!$E$4:$E$501,'Partial Payment Log'!$C$4:$C$501,A36)) -> 0 | Q36: =IF(A36="","",K36-P36) -> 254886.8 | R36: =IF(A36="","",IF(Q36<=0,IF(Q36<0,"Overpaid","Paid"),IF(P36>0,"Part Paid","Unpaid"))) -> Unpaid
A37: AEI11 | B37: ARYAN GEMS | C37: 46196 | D37: 9 | E37: 49000 | F37: =IF(OR(D37="",E37=""),"",D37*E37) -> 441000 | G37: 4.12 | H37: =IF(A37="","",N(G37)*E37) -> 201880 | I37: =IF(F37="","",(F37-H37)*1.5%) -> 3586.8 | J37: =IF(F37="","",(F37-H37)+I37) -> 242706.8 | K37: =IF(F37="","",J37) -> 242706.8 | L37: 90 | M37: =IF(OR(C37="",L37=""),"",C37+L37) -> 46286 | N37: =IF(M37="","",M37-TODAY()) -> -11 | O37: =IF(L37="","",L37&" Day Due") -> 90 Day Due | P37: =IF(A37="","",SUMIFS('Partial Payment Log'!$E$4:$E$501,'Partial Payment Log'!$C$4:$C$501,A37)) -> 0 | Q37: =IF(A37="","",K37-P37) -> 242706.8 | R37: =IF(A37="","",IF(Q37<=0,IF(Q37<0,"Overpaid","Paid"),IF(P37>0,"Part Paid","Unpaid"))) -> Unpaid
... A71: AG208 | B71: ARYAN GEMS | C71: 46272 | D71: 40.095 | E71: 41000 | F71: =IF(OR(D71="",E71=""),"",D71*E71) -> 1643895 | G71: 0 | H71: =IF(A71="","",N(G71)*E71) -> 0 | I71: =IF(F71="","",(F71-H71)*1.5%) -> 24658.425 | J71: =IF(F71="","",(F71-H71)+I71) -> 1668553.4 | K71: =IF(F71="","",J71) -> 1668553.4 | L71: 90 | M71: =IF(OR(C71="",L71=""),"",C71+L71) -> 46362 | N71: =IF(M71="","",M71-TODAY()) -> 65 | O71: =IF(L71="","",L71&" Day Due") -> 90 Day Due | P71: =IF(A71="","",SUMIFS('Partial Payment Log'!$E$4:$E$501,'Partial Payment Log'!$C$4:$C$501,A71)) -> 0 | Q71: =IF(A71="","",K71-P71) -> 1668553.4 | R71: =IF(A71="","",IF(Q71<=0,IF(Q71<0,"Overpaid","Paid"),IF(P71>0,"Part Paid","Unpaid"))) -> Unpaid
A72: AV0060 | B72: AV DIAMONDS | C72: 46276 | D72: 73.16 | E72: 41000 | F72: =IF(OR(D72="",E72=""),"",D72*E72) -> 2999560 | G72: 0 | H72: =IF(A72="","",N(G72)*E72) -> 0 | I72: =IF(F72="","",(F72-H72)*1.5%) -> 44993.4 | J72: =IF(F72="","",(F72-H72)+I72) -> 3044553.4 | K72: =IF(F72="","",J72) -> 3044553.4 | M72: =IF(OR(C72="",L72=""),"",C72+L72) | N72: =IF(M72="","",M72-TODAY()) | O72: =IF(L72="","",L72&" Day Due") | P72: =IF(A72="","",SUMIFS('Partial Payment Log'!$E$4:$E$501,'Partial Payment Log'!$C$4:$C$501,A72)) -> 0 | Q72: =IF(A72="","",K72-P72) -> 3044553.4 | R72: =IF(A72="","",IF(Q72<=0,IF(Q72<0,"Overpaid","Paid"),IF(P72>0,"Part Paid","Unpaid"))) -> Unpaid
F73: =IF(OR(D73="",E73=""),"",D73*E73) | H73: =IF(A73="","",N(G73)*E73) | I73: =IF(F73="","",(F73-H73)*1.5%) | J73: =IF(F73="","",(F73-H73)+I73) | K73: =IF(F73="","",J73) | M73: =IF(OR(C73="",L73=""),"",C73+L73) | N73: =IF(M73="","",M73-TODAY()) | O73: =IF(L73="","",L73&" Day Due") | P73: =IF(A73="","",SUMIFS('Partial Payment Log'!$E$4:$E$501,'Partial Payment Log'!$C$4:$C$501,A73)) | Q73: =IF(A73="","",K73-P73) | R73: =IF(A73="","",IF(Q73<=0,IF(Q73<0,"Overpaid","Paid"),IF(P73>0,"Part Paid","Unpaid")))
F74: =IF(OR(D74="",E74=""),"",D74*E74) | H74: =IF(A74="","",N(G74)*E74) | I74: =IF(F74="","",(F74-H74)*1.5%) | J74: =IF(F74="","",(F74-H74)+I74) | K74: =IF(F74="","",J74) | M74: =IF(OR(C74="",L74=""),"",C74+L74) | N74: =IF(M74="","",M74-TODAY()) | O74: =IF(L74="","",L74&" Day Due") | P74: =IF(A74="","",SUMIFS('Partial Payment Log'!$E$4:$E$501,'Partial Payment Log'!$C$4:$C$501,A74)) | Q74: =IF(A74="","",K74-P74) | R74: =IF(A74="","",IF(Q74<=0,IF(Q74<0,"Overpaid","Paid"),IF(P74>0,"Part Paid","Unpaid")))
...

Sheet Partial Payment Log
A1: PARTIAL PAYMENT LOG - ENTER EVERY PAYMENT HERE
A2: For one invoice, add many payment rows here. The tracker will calculate total paid and balance automatically.
A3: Payment Date | B3: Supplier Name | C3: Invoice No | D3: Invoice Amount | E3: Payment Amount | F3: Payment Mode
A4: 01-04-2026 | B4: JEEYA DIAMOND | C4: OPEN-JEEYA | D4: =IF(C4="","",IFERROR(INDEX('Purchase Tracker'!$J$4:$J$300,MATCH(C4,'Purchase Tracker'!$A$4:$A$300,0)),"")) -> 10020689 | E4: 1500000 | F4: RTGS/NEFT
A5: 18-04-2026 | B5: JEEYA DIAMOND | C5: OPEN-JEEYA | D5: =IF(C5="","",IFERROR(INDEX('Purchase Tracker'!$J$4:$J$300,MATCH(C5,'Purchase Tracker'!$A$4:$A$300,0)),"")) -> 10020689 | E5: 1400000 | F5: RTGS/NEFT
A6: 23-04-2026 | B6: JEEYA DIAMOND | C6: OPEN-JEEYA | D6: =IF(C6="","",IFERROR(INDEX('Purchase Tracker'!$J$4:$J$300,MATCH(C6,'Purchase Tracker'!$A$4:$A$300,0)),"")) -> 10020689 | E6: 501192 | F6: RTGS/NEFT
A7: 30-04-2026 | B7: JEEYA DIAMOND | C7: OPEN-JEEYA | D7: =IF(C7="","",IFERROR(INDEX('Purchase Tracker'!$J$4:$J$300,MATCH(C7,'Purchase Tracker'!$A$4:$A$300,0)),"")) -> 10020689 | E7: 1000000 | F7: RTGS/NEFT
A8: 22-05-2026 | B8: JEEYA DIAMOND | C8: OPEN-JEEYA | D8: =IF(C8="","",IFERROR(INDEX('Purchase Tracker'!$J$4:$J$300,MATCH(C8,'Purchase Tracker'!$A$4:$A$300,0)),"")) -> 10020689 | E8: 1500000 | F8: RTGS/NEFT
A9: 11-06-2026 | B9: JEEYA DIAMOND | C9: OPEN-JEEYA | D9: =IF(C9="","",IFERROR(INDEX('Purchase Tracker'!$J$4:$J$300,MATCH(C9,'Purchase Tracker'!$A$4:$A$300,0)),"")) -> 10020689 | E9: 1000000 | F9: RTGS/NEFT
A10: 16-06-2026 | B10: JEEYA DIAMOND | C10: OPEN-JEEYA | D10: =IF(C10="","",IFERROR(INDEX('Purchase Tracker'!$J$4:$J$300,MATCH(C10,'Purchase Tracker'!$A$4:$A$300,0)),"")) -> 10020689 | E10: 1500000 | F10: RTGS/NEFT
A11: 24-06-2026 | B11: JEEYA DIAMOND | C11: OPEN-JEEYA | D11: =IF(C11="","",IFERROR(INDEX('Purchase Tracker'!$J$4:$J$300,MATCH(C11,'Purchase Tracker'!$A$4:$A$300,0)),"")) -> 10020689 | E11: 1500000 | F11: RTGS/NEFT
A12: 11-04-2026 | B12: RITESH EXPORT | C12: OPEN--RITESH | D12: =IF(C12="","",IFERROR(INDEX('Purchase Tracker'!$J$4:$J$300,MATCH(C12,'Purchase Tracker'!$A$4:$A$300,0)),"")) -> 6259315 | E12: 1000000 | F12: RTGS/NEFT
A13: 24-04-2026 | B13: RITESH EXPORT | C13: OPEN--RITESH | D13: =IF(C13="","",IFERROR(INDEX('Purchase Tracker'!$J$4:$J$300,MATCH(C13,'Purchase Tracker'!$A$4:$A$300,0)),"")) -> 6259315 | E13: 1000000 | F13: RTGS/NEFT
A14: 05-05-2026 | B14: RITESH EXPORT | C14: OPEN--RITESH | D14: =IF(C14="","",IFERROR(INDEX('Purchase Tracker'!$J$4:$J$300,MATCH(C14,'Purchase Tracker'!$A$4:$A$300,0)),"")) -> 6259315 | E14: 1000000 | F14: RTGS/NEFT
A15: 18-05-2026 | B15: RITESH EXPORT | C15: OPEN--RITESH | D15: =IF(C15="","",IFERROR(INDEX('Purchase Tracker'!$J$4:$J$300,MATCH(C15,'Purchase Tracker'!$A$4:$A$300,0)),"")) -> 6259315 | E15: 1000000 | F15: RTGS/NEFT
A16: 27-05-2026 | B16: RITESH EXPORT | C16: OPEN--RITESH | D16: =IF(C16="","",IFERROR(INDEX('Purchase Tracker'!$J$4:$J$300,MATCH(C16,'Purchase Tracker'!$A$4:$A$300,0)),"")) -> 6259315 | E16: 1000000 | F16: RTGS/NEFT
A17: 46184 | B17: RITESH EXPORT | C17: OPEN--RITESH | D17: =IF(C17="","",IFERROR(INDEX('Purchase Tracker'!$J$4:$J$300,MATCH(C17,'Purchase Tracker'!$A$4:$A$300,0)),"")) -> 6259315 | E17: 1000000 | F17: RTGS/NEFT
A18: 11-04-2026 | B18: APPLE GEMS | C18: OPEN-APPLE | D18: =IF(C18="","",IFERROR(INDEX('Purchase Tracker'!$J$4:$J$300,MATCH(C18,'Purchase Tracker'!$A$4:$A$300,0)),"")) -> 16111567 | E18: 1000000 | F18: RTGS/NEFT
A19: 23-04-2026 | B19: APPLE GEMS | C19: OPEN-APPLE | D19: =IF(C19="","",IFERROR(INDEX('Purchase Tracker'!$J$4:$J$300,MATCH(C19,'Purchase Tracker'!$A$4:$A$300,0)),"")) -> 16111567 | E19: 201604 | F19: RTGS/NEFT
A20: 27-05-2026 | B20: APPLE GEMS | C20: OPEN-APPLE | D20: =IF(C20="","",IFERROR(INDEX('Purchase Tracker'!$J$4:$J$300,MATCH(C20,'Purchase Tracker'!$A$4:$A$300,0)),"")) -> 16111567 | E20: 1000000 | F20: RTGS/NEFT
A21: 03-06-2026 | B21: APPLE GEMS | C21: OPEN-APPLE | D21: =IF(C21="","",IFERROR(INDEX('Purchase Tracker'!$J$4:$J$300,MATCH(C21,'Purchase Tracker'!$A$4:$A$300,0)),"")) -> 16111567 | E21: 1000000 | F21: RTGS/NEFT
A22: 11-06-2026 | B22: APPLE GEMS | C22: OPEN-APPLE | D22: =IF(C22="","",IFERROR(INDEX('Purchase Tracker'!$J$4:$J$300,MATCH(C22,'Purchase Tracker'!$A$4:$A$300,0)),"")) -> 16111567 | E22: 1000000 | F22: RTGS/NEFT
A23: 24-06-2026 | B23: APPLE GEMS | C23: OPEN-APPLE | D23: =IF(C23="","",IFERROR(INDEX('Purchase Tracker'!$J$4:$J$300,MATCH(C23,'Purchase Tracker'!$A$4:$A$300,0)),"")) -> 16111567 | E23: 1000000 | F23: RTGS/NEFT
A24: 13-04-2026 | B24: S & M DIAMONDS . | C24: OPEN-S&M | D24: =IF(C24="","",IFERROR(INDEX('Purchase Tracker'!$J$4:$J$300,MATCH(C24,'Purchase Tracker'!$A$4:$A$300,0)),"")) -> 3984422 | E24: 1139221 | F24: RTGS/NEFT
A25: 22-05-2026 | B25: S & M DIAMONDS . | C25: OPEN-S&M | D25: =IF(C25="","",IFERROR(INDEX('Purchase Tracker'!$J$4:$J$300,MATCH(C25,'Purchase Tracker'!$A$4:$A$300,0)),"")) -> 3984422 | E25: 1000000 | F25: RTGS/NEFT
A26: 18-06-2026 | B26: S & M DIAMONDS . | C26: OPEN-S&M | D26: =IF(C26="","",IFERROR(INDEX('Purchase Tracker'!$J$4:$J$300,MATCH(C26,'Purchase Tracker'!$A$4:$A$300,0)),"")) -> 3984422 | E26: 845000 | F26: RTGS/NEFT
A27: 24-06-2026 | B27: S & M DIAMONDS . | C27: OPEN-S&M | D27: =IF(C27="","",IFERROR(INDEX('Purchase Tracker'!$J$4:$J$300,MATCH(C27,'Purchase Tracker'!$A$4:$A$300,0)),"")) -> 3984422 | E27: 1000000 | F27: RTGS/NEFT
A28: 11-04-2026 | B28: AV DIAMONDS | C28: OPEN-AV | D28: =IF(C28="","",IFERROR(INDEX('Purchase Tracker'!$J$4:$J$300,MATCH(C28,'Purchase Tracker'!$A$4:$A$300,0)),"")) -> 18652765 | E28: 1000000 | F28: RTGS/NEFT
A29: 18-04-2026 | B29: AV DIAMONDS | C29: OPEN-AV | D29: =IF(C29="","",IFERROR(INDEX('Purchase Tracker'!$J$4:$J$300,MATCH(C29,'Purchase Tracker'!$A$4:$A$300,0)),"")) -> 18652765 | E29: 944250 | F29: RTGS/NEFT
... A39: 01-07-2026 | B39: AV DIAMONDS | C39: OPEN-AV | D39: =IF(C39="","",IFERROR(INDEX('Purchase Tracker'!$J$4:$J$300,MATCH(C39,'Purchase Tracker'!$A$4:$A$300,0)),"")) -> 18652765 | E39: 1000000 | F39: RTGS/NEFT
A40: 46136 | B40: BHAVYA JEWELS | C40: OPEN -BAV | D40: =IF(C40="","",IFERROR(INDEX('Purchase Tracker'!$J$4:$J$300,MATCH(C40,'Purchase Tracker'!$A$4:$A$300,0)),"")) -> 3101354 | E40: 1000000 | F40: RTGS/NEFT
A41: 46113 | B41: ARYAN GEMS | C41: OPEN-ARIA | D41: =IF(C41="","",IFERROR(INDEX('Purchase Tracker'!$J$4:$J$300,MATCH(C41,'Purchase Tracker'!$A$4:$A$300,0)),"")) -> 11154524 | E41: 500000 | F41: RTGS/NEFT
A42: 46125 | B42: ARYAN GEMS | C42: OPEN-ARIA | D42: =IF(C42="","",IFERROR(INDEX('Purchase Tracker'!$J$4:$J$300,MATCH(C42,'Purchase Tracker'!$A$4:$A$300,0)),"")) -> 11154524 | E42: 600000 | F42: RTGS/NEFT
A43: 46130 | B43: ARYAN GEMS | C43: OPEN-ARIA | D43: =IF(C43="","",IFERROR(INDEX('Purchase Tracker'!$J$4:$J$300,MATCH(C43,'Purchase Tracker'!$A$4:$A$300,0)),"")) -> 11154524 | E43: 600000 | F43: RTGS/NEFT
A44: 46135 | B44: ARYAN GEMS | C44: OPEN-ARIA | D44: =IF(C44="","",IFERROR(INDEX('Purchase Tracker'!$J$4:$J$300,MATCH(C44,'Purchase Tracker'!$A$4:$A$300,0)),"")) -> 11154524 | E44: 605037 | F44: RTGS/NEFT
A45: 46142 | B45: ARYAN GEMS | C45: OPEN-ARIA | D45: =IF(C45="","",IFERROR(INDEX('Purchase Tracker'!$J$4:$J$300,MATCH(C45,'Purchase Tracker'!$A$4:$A$300,0)),"")) -> 11154524 | E45: 1000000 | F45: RTGS/NEFT
A46: 46155 | B46: ARYAN GEMS | C46: OPEN-ARIA | D46: =IF(C46="","",IFERROR(INDEX('Purchase Tracker'!$J$4:$J$300,MATCH(C46,'Purchase Tracker'!$A$4:$A$300,0)),"")) -> 11154524 | E46: 1000000 | F46: RTGS/NEFT
A47: 46164 | B47: ARYAN GEMS | C47: OPEN-ARIA | D47: =IF(C47="","",IFERROR(INDEX('Purchase Tracker'!$J$4:$J$300,MATCH(C47,'Purchase Tracker'!$A$4:$A$300,0)),"")) -> 11154524 | E47: 1000000 | F47: RTGS/NEFT
A48: 46181 | B48: ARYAN GEMS | C48: OPEN-ARIA | D48: =IF(C48="","",IFERROR(INDEX('Purchase Tracker'!$J$4:$J$300,MATCH(C48,'Purchase Tracker'!$A$4:$A$300,0)),"")) -> 11154524 | E48: 1000000 | F48: RTGS/NEFT
A49: 46189 | B49: ARYAN GEMS | C49: OPEN-ARIA | D49: =IF(C49="","",IFERROR(INDEX('Purchase Tracker'!$J$4:$J$300,MATCH(C49,'Purchase Tracker'!$A$4:$A$300,0)),"")) -> 11154524 | E49: 2684907 | F49: RTGS/NEFT
...

Sheet Dashboard
A1: DIAMOND SUPPLIER PAYMENT DASHBOARD
A3: Total Full Amount | B3: =SUM('Purchase Tracker'!F4:F300) -> 1.6727485e+08
A4: Sales Return Amount | B4: =SUM('Purchase Tracker'!H4:H300) -> 16768306
A5: Tax 1.5% on Net Purchase | B5: =SUM('Purchase Tracker'!I4:I300) -> 2257598.1
A6: Total After Return + Tax | B6: =SUM('Purchase Tracker'!J4:J300) -> 1.5276414e+08
A7: Net Payable | B7: =SUM('Purchase Tracker'!K4:K300) -> 1.5276414e+08
A8: Total Paid Amount | B8: =SUM('Purchase Tracker'!P4:P300) -> 92993198
A9: Total Balance Amount | B9: =SUM('Purchase Tracker'!Q4:Q300) -> 59770943
A10: Overdue Balance | B10: =SUMIFS('Purchase Tracker'!Q4:Q300,'Purchase Tracker'!N4:N300,"<0") -> 22868549
A12: Supplier Name | B12: Total Net Payable | C12: Total Paid | D12: Balance | E12: Overdue Balance | F12: FLAG
A13: APPLE GEMS | B13: =SUMIFS('Purchase Tracker'!$K$4:$K$300,'Purchase Tracker'!$B$4:$B$300,A13) -> 16111567 | C13: =SUMIFS('Purchase Tracker'!$P$4:$P$300,'Purchase Tracker'!$B$4:$B$300,A13) -> 16124397 | D13: =SUMIFS('Purchase Tracker'!$Q$4:$Q$300,'Purchase Tracker'!$B$4:$B$300,A13) -> -12830 | E13: =SUMIFS('Purchase Tracker'!$Q$4:$Q$300,'Purchase Tracker'!$B$4:$B$300,A13,'Purchase Tracker'!$N$4:$N$300,"<0") -> -12830
A14: AV DIAMONDS | B14: =SUMIFS('Purchase Tracker'!$K$4:$K$300,'Purchase Tracker'!$B$4:$B$300,A14) -> 44896179 | C14: =SUMIFS('Purchase Tracker'!$P$4:$P$300,'Purchase Tracker'!$B$4:$B$300,A14) -> 22927511 | D14: =SUMIFS('Purchase Tracker'!$Q$4:$Q$300,'Purchase Tracker'!$B$4:$B$300,A14) -> 21968668 | E14: =SUMIFS('Purchase Tracker'!$Q$4:$Q$300,'Purchase Tracker'!$B$4:$B$300,A14,'Purchase Tracker'!$N$4:$N$300,"<0") -> 2610563.2
A15: SHINESTONE DIAM LLP | B15: =SUMIFS('Purchase Tracker'!$K$4:$K$300,'Purchase Tracker'!$B$4:$B$300,A15) -> 13456160 | C15: =SUMIFS('Purchase Tracker'!$P$4:$P$300,'Purchase Tracker'!$B$4:$B$300,A15) -> 13456160 | D15: =SUMIFS('Purchase Tracker'!$Q$4:$Q$300,'Purchase Tracker'!$B$4:$B$300,A15) -> 0 | E15: =SUMIFS('Purchase Tracker'!$Q$4:$Q$300,'Purchase Tracker'!$B$4:$B$300,A15,'Purchase Tracker'!$N$4:$N$300,"<0") -> 0
A16: BHAVYA JEWELS | B16: =SUMIFS('Purchase Tracker'!$K$4:$K$300,'Purchase Tracker'!$B$4:$B$300,A16) -> 5396329.9 | C16: =SUMIFS('Purchase Tracker'!$P$4:$P$300,'Purchase Tracker'!$B$4:$B$300,A16) -> 3000000 | D16: =SUMIFS('Purchase Tracker'!$Q$4:$Q$300,'Purchase Tracker'!$B$4:$B$300,A16) -> 2396329.9 | E16: =SUMIFS('Purchase Tracker'!$Q$4:$Q$300,'Purchase Tracker'!$B$4:$B$300,A16,'Purchase Tracker'!$N$4:$N$300,"<0") -> 1349986.7
A17: JEEYA DIAMOND | B17: =SUMIFS('Purchase Tracker'!$K$4:$K$300,'Purchase Tracker'!$B$4:$B$300,A17) -> 25577645 | C17: =SUMIFS('Purchase Tracker'!$P$4:$P$300,'Purchase Tracker'!$B$4:$B$300,A17) -> 10901192 | D17: =SUMIFS('Purchase Tracker'!$Q$4:$Q$300,'Purchase Tracker'!$B$4:$B$300,A17) -> 14676453 | E17: =SUMIFS('Purchase Tracker'!$Q$4:$Q$300,'Purchase Tracker'!$B$4:$B$300,A17,'Purchase Tracker'!$N$4:$N$300,"<0") -> 7583785
A18: S & M DIAMONDS . | B18: =SUMIFS('Purchase Tracker'!$K$4:$K$300,'Purchase Tracker'!$B$4:$B$300,A18) -> 9309127.2 | C18: =SUMIFS('Purchase Tracker'!$P$4:$P$300,'Purchase Tracker'!$B$4:$B$300,A18) -> 6984221 | D18: =SUMIFS('Purchase Tracker'!$Q$4:$Q$300,'Purchase Tracker'!$B$4:$B$300,A18) -> 2324906.2 | E18: =SUMIFS('Purchase Tracker'!$Q$4:$Q$300,'Purchase Tracker'!$B$4:$B$300,A18,'Purchase Tracker'!$N$4:$N$300,"<0") -> 2324906.2
A19: ARYAN GEMS | B19: =SUMIFS('Purchase Tracker'!$K$4:$K$300,'Purchase Tracker'!$B$4:$B$300,A19) -> 29350159 | C19: =SUMIFS('Purchase Tracker'!$P$4:$P$300,'Purchase Tracker'!$B$4:$B$300,A19) -> 12989944 | D19: =SUMIFS('Purchase Tracker'!$Q$4:$Q$300,'Purchase Tracker'!$B$4:$B$300,A19) -> 16360215 | E19: =SUMIFS('Purchase Tracker'!$Q$4:$Q$300,'Purchase Tracker'!$B$4:$B$300,A19,'Purchase Tracker'!$N$4:$N$300,"<0") -> 9012138.2
A20: RITESH EXPORT | B20: =SUMIFS('Purchase Tracker'!$K$4:$K$300,'Purchase Tracker'!$B$4:$B$300,A20) -> 8666976 | C20: =SUMIFS('Purchase Tracker'!$P$4:$P$300,'Purchase Tracker'!$B$4:$B$300,A20) -> 6609774 | D20: =SUMIFS('Purchase Tracker'!$Q$4:$Q$300,'Purchase Tracker'!$B$4:$B$300,A20) -> 2057202 | E20: =SUMIFS('Purchase Tracker'!$Q$4:$Q$300,'Purchase Tracker'!$B$4:$B$300,A20,'Purchase Tracker'!$N$4:$N$300,"<0") -> 5.8207661e-11
A21: KUSHION DANDH | B21: =SUMIFS('Purchase Tracker'!$K$4:$K$300,'Purchase Tracker'!$B$4:$B$300,A21) -> 0 | C21: =SUMIFS('Purchase Tracker'!$P$4:$P$300,'Purchase Tracker'!$B$4:$B$300,A21) -> 0 | D21: =SUMIFS('Purchase Tracker'!$Q$4:$Q$300,'Purchase Tracker'!$B$4:$B$300,A21) -> 0 | E21: =SUMIFS('Purchase Tracker'!$Q$4:$Q$300,'Purchase Tracker'!$B$4:$B$300,A21,'Purchase Tracker'!$N$4:$N$300,"<0") -> 0

Sheet Supplier Master
A1: Supplier Name | B1: Contact Person | C1: Phone | D1: Email | E1: Address | F1: Default Payment Term | G1: Opening Balance | H1: Remarks | I1: C/O | J1: Phone2
A2: APPLE GEMS | B2: VALLAB BHAI | C2: 9892459129 | E2: C/O Paul | F2: 90 | G2: 0 | I2: PAUL | J2: 7356503187
A3: AV DIAMONDS | B3: SALVIN | C3: 9048856868 | E3: THR Diamond Supplair | F3: 90 | G3: 0
A4: SHINESTONE DIAM LLP | B4: RAJU BAI | C4: 9321455755 | E4: MUMBAI BKC Supplair | F4: 90 | G4: 0
A5: GALAXY DIAMONDS | B5: LAZER | C5: 9747643707 | E5: THR Diamond Supplair | F5: 90 | G5: 0
A6: BHAVYA JEWELS | B6: NARESH | C6: 9824345340 | E6: SURAT Diamond Supplair | F6: 90 | G6: 0
A7: JEEYA DIAMOND | B7: KIRAN | C7: 9870728848 | E7: MUMBAI Diamond Supplair | F7: 90 | G7: 0
A8: S & M DIAMONDS . | B8: LALIT | C8: 9820384200 | F8: 90 | G8: 0
A9: ARYAN GEMS | B9: JIJO | C9: 9526329840 | E9: THR Diamond Supplair | F9: 90 | G9: 0
A10: RITESH EXPORT | B10: ILESH | C10: 9769490893 | E10: C/O SHIVADAS | F10: 90 | G10: 0 | I10: SIVADAS | J10: 7034536857
A11: KUSHION DANDH | B11: KUSHION | C11: 9892199776 | F11: 90 | G11: 0

Sheet Lists
A1: Payment Terms | B1: Payment Mode
A2: 30 | B2: Cash
A3: 60 | B3: RTGS/NEFT
A4: 90 | B4: UPI
A5: 120 | B5: Cheque
B6: Bank Transfer
B7: Other
